<?xml version="1.0"?>
<robot name="simple_biped_3D">

  <material name="blue">
    <color rgba="0 0 1 1"/>
  </material>

  <material name="green">
    <color rgba="0 1 0 1"/>
  </material>

  <material name="red">
    <color rgba="1 0 0 1"/>
  </material>

  <!-- Base link -->
  <link name="base">
    <inertial>
      <origin xyz="0 0 0.1" rpy="0 0 0"/>
      <mass value="10.0"/>
      <inertia ixx="1" ixy="0" ixz="0" iyy="1" iyz="0" izz="1"/>
    </inertial>
    <visual>
      <origin xyz="0 0 0.1" rpy="0 0 0"/>
      <geometry>
        <box size="0.2 0.1 0.2"/>
      </geometry>
      <material name="green"/>
    </visual>
    <collision>
      <origin xyz="0 0 0.1" rpy="0 0 0"/>
      <geometry>
        <box size="0.2 0.1 0.2"/>
      </geometry>
    </collision>
  </link>

  <!-- Right leg -->
  <link name="right_leg">
    <inertial>
      <origin xyz="0 -0.05 -0.4" rpy="0 0 0"/>
      <mass value="3.0"/>
      <inertia ixx="0.1" ixy="0" ixz="0" iyy="0.1" iyz="0" izz="0.1"/>
    </inertial>
    <visual>
      <origin xyz="0 -0.05 -0.4" rpy="0 0 0"/>
      <geometry>
        <cylinder length="0.8" radius="0.05"/>
      </geometry>
      <material name="red"/>
    </visual>
    <collision>
      <origin xyz="0 -0.05 -0.4" rpy="0 0 0"/>
      <geometry>
        <cylinder length="0.8" radius="0.05"/>
      </geometry>
    </collision>
  </link>

  <!-- Left leg -->
  <link name="left_leg">
    <inertial>
      <origin xyz="0 0.05 -0.4" rpy="0 0 0"/>
      <mass value="3.0"/>
      <inertia ixx="0.1" ixy="0" ixz="0" iyy="0.1" iyz="0" izz="0.1"/>
    </inertial>
    <visual>
      <origin xyz="0 0.05 -0.4" rpy="0 0 0"/>
      <geometry>
        <cylinder length="0.8" radius="0.05"/>
      </geometry>
      <material name="blue"/>
    </visual>
    <collision>
      <origin xyz="0 0.05 -0.4" rpy="0 0 0"/>
      <geometry>
        <cylinder length="0.8" radius="0.05"/>
      </geometry>
    </collision>
  </link>

  <!-- Joints -->
  <!-- Right hip joint -->
  <joint name="right_hip_joint" type="revolute">
    <origin xyz="0 -0.05 0" rpy="0 0 0"/>
    <parent link="base"/>
    <child link="right_leg"/>
    <axis xyz="0 1 0"/>
    <limit lower="-1.57" upper="1.57" effort="100" velocity="1.0"/>
  </joint>

  <!-- Left hip joint -->
  <joint name="left_hip_joint" type="revolute">
    <origin xyz="0 0.05 0" rpy="0 0 0"/>
    <parent link="base"/>
    <child link="left_leg"/>
    <axis xyz="0 1 0"/>
    <limit lower="-1.57" upper="1.57" effort="100" velocity="1.0"/>
  </joint>

  <!-- Right lower leg -->
  <link name="right_lower_leg">
    <inertial>
      <origin xyz="0 -0.05 -0.6" rpy="0 0 0"/>
      <mass value="2.0"/>
      <inertia ixx="0.05" ixy="0" ixz="0" iyy="0.05" iyz="0" izz="0.05"/>
    </inertial>
    <visual>
      <origin xyz="0 -0.05 -0.6" rpy="0 0 0"/>
      <geometry>
        <cylinder length="0.6" radius="0.04"/>
      </geometry>
      <material name="red"/>
    </visual>
    <collision>
      <origin xyz="0 -0.05 -0.6" rpy="0 0 0"/>
      <geometry>
        <cylinder length="0.6" radius="0.04"/>
      </geometry>
    </collision>
  </link>

  <!-- Left lower leg -->
  <link name="left_lower_leg">
    <inertial>
      <origin xyz="0 0.05 -0.6" rpy="0 0 0"/>
      <mass value="2.0"/>
      <inertia ixx="0.05" ixy="0" ixz="0" iyy="0.05" iyz="0" izz="0.05"/>
    </inertial>
    <visual>
      <origin xyz="0 0.05 -0.6" rpy="0 0 0"/>
      <geometry>
        <cylinder length="0.6" radius="0.04"/>
      </geometry>
      <material name="blue"/>
    </visual>
    <collision>
      <origin xyz="0 0.05 -0.6" rpy="0 0 0"/>
      <geometry>
        <cylinder length="0.6" radius="0.04"/>
      </geometry>
    </collision>
  </link>

  <!-- Right knee joint -->
  <joint name="right_knee_joint" type="revolute">
    <origin xyz="0 -0.05 -0.8" rpy="0 0 0"/>
    <parent link="right_leg"/>
    <child link="right_lower_leg"/>
    <axis xyz="0 1 0"/>
    <limit lower="0" upper="1.57" effort="100" velocity="1.0"/>
  </joint>

  <!-- Left knee joint -->
  <joint name="left_knee_joint" type="revolute">
    <origin xyz="0 0.05 -0.8" rpy="0 0 0"/>
    <parent link="left_leg"/>
    <child link="left_lower_leg"/>
    <axis xyz="0 1 0"/>
    <limit lower="0" upper="1.57" effort="100" velocity="1.0"/>
  </joint>


</robot>
